Workbook

Sheet Cover
B2: MUSIC DOWNLOADER
B4: BÁO CÁO TEST CASE - AUTOMATION TEST (Appium / Java / TestNG)
B6: Ứng dụng | C6: Music Downloader (Android)
B7: Thiết bị kiểm thử | C7: Oppo Pad Neo - Android 14 (1720 x 2408)
B8: Công cụ | C8: Appium 2.x, Java 21, TestNG, ExtentReports
B9: Mô hình | C9: Page Object Model (POM)
B10: Tổng số chức năng | C10: 8
B11: Tổng số test class | C11: 47
B12: Tổng số test case | C12: 255
B13: Ngày cập nhật | C13: 2026-06-10
B15: QUY ƯỚC
B16: Priority | C16: High = quan trọng (business rule, E2E, play controls) · Medium = chính · Low = phụ
B17: Type | C17: UI = hiển thị · Functional = chức năng · Negative = ca lỗi/biên · E2E = luồng đầu-cuối
B18: Status | C18: Pass · Fail · Blocked · Not Run (mặc định để QA cập nhật khi chạy)
B19: Ghi chú | C19: DESTRUCTIVE = thao tác xóa dữ liệu · Business rule = quy tắc giới hạn share 10 bài

Sheet Test Cases
A1: STT | B1: Test Case ID | C1: Chức năng | D1: Test Suite (Class) | E1: Tên / Mục đích Test Case | F1: Loại | G1: Ưu tiên | H1: Kết quả mong đợi | I1: Trạng thái | J1: Ghi chú
A2: 1 | B2: TC_HOME_001 | C2: Home | D2: Home01_Verify_App_Launched | E2: Khởi động app và bỏ qua quảng cáo thành công | F2: Functional | G2: High | H2: App mở được Home, không bị kẹt ở màn quảng cáo | I2: Not Run
A3: 2 | B3: TC_HOME_002 | C3: Home | D3: Home02_Verify_Bypass_Ad_After_Interaction | E3: Tự động bỏ qua quảng cáo bung giữa phiên và chạy tiếp | F3: Functional | G3: High | H3: Quảng cáo bị đóng tự động, app tiếp tục hoạt động | I3: Not Run
A4: 3 | B4: TC_HOME_003 | C4: Home | D4: Home03_Verify_UI_Display | E4: Hiển thị tiêu đề Home | F4: UI | G4: Medium | H4: Tiêu đề 'Home' hiển thị đúng | I4: Not Run
A5: 4 | B5: TC_HOME_004 | C5: Home | D5: Home03_Verify_UI_Display | E5: Hiển thị icon hamburger menu | F5: UI | G5: Medium | H5: Icon menu (góc trái) hiển thị | I5: Not Run
A6: 5 | B6: TC_HOME_005 | C6: Home | D6: Home03_Verify_UI_Display | E6: Hiển thị icon tìm kiếm góc phải | F6: UI | G6: Medium | H6: Icon search (góc phải) hiển thị | I6: Not Run
A7: 6 | B7: TC_HOME_006 | C7: Home | D7: Home03_Verify_UI_Display | E7: Hiển thị thanh search với placeholder | F7: UI | G7: Medium | H7: Thanh 'Search music online...' hiển thị đúng placeholder | I7: Not Run
A8: 7 | B8: TC_HOME_007 | C8: Home | D8: Home03_Verify_UI_Display | E8: Hiển thị 4 nút Quick Action | F8: UI | G8: Medium | H8: 4 nút Downloaded / Sleep timer / Rate us / Settings hiển thị | I8: Not Run
A9: 8 | B9: TC_HOME_008 | C9: Home | D9: Home03_Verify_UI_Display | E9: Hiển thị Mini Player | F9: UI | G9: Medium | H9: Mini player hiển thị khi có bài đang phát | I9: Not Run
A10: 9 | B10: TC_HOME_009 | C10: Home | D10: Home03_Verify_UI_Display | E10: Hiển thị Bottom Navigation 5 tab | F10: UI | G10: Medium | H10: Bottom nav có đủ 5 tab Home/Tracks/Artists/Albums/Playlists | I10: Not Run
A11: 10 | B11: TC_HOME_010 | C11: Home | D11: Home03_Verify_UI_Display | E11: Hiển thị tổng thể màn Home | F11: UI | G11: Medium | H11: Toàn bộ thành phần Home hiển thị đầy đủ, đúng bố cục | I11: Not Run
A12: 11 | B12: TC_HOME_011 | C12: Home | D12: Home04_Verify_Quick_Actions | E12: Click thanh search mở màn Search | F12: Functional | G12: Medium | H12: Chuyển sang màn Search music online | I12: Not Run
A13: 12 | B13: TC_HOME_012 | C13: Home | D13: Home04_Verify_Quick_Actions | E13: Click icon search góc phải mở Search In Library | F13: Functional | G13: Medium | H13: Chuyển sang màn Search In Library | I13: Not Run
... A30: 29 | B30: TC_HOME_029 | C30: Home | D30: Home06_Verify_Exit_Dialog | E30: Bấm Cancel trên exit dialog ở lại Home | F30: Functional | G30: Medium | H30: Dialog đóng, app vẫn ở Home | I30: Not Run
A31: 30 | B31: TC_HOME_030 | C31: Home | D31: Home06_Verify_Exit_Dialog | E31: Bấm Exit trên exit dialog thoát app | F31: Functional | G31: Low | H31: App đóng hoàn toàn | I31: Not Run | J31: DESTRUCTIVE
A32: 31 | B32: TC_DL_001 | C32: Search Online (Download) | D32: Search01_Verify_Navigation | E32: Click thanh search chuyển sang màn Search | F32: Functional | G32: Medium | H32: Mở màn Search music online | I32: Not Run
A33: 32 | B33: TC_DL_002 | C33: Search Online (Download) | D33: Search01_Verify_Navigation | E33: Vào Search bàn phím hiện để nhập | F33: Functional | G33: Low | H33: Bàn phím tự bật khi vào màn Search | I33: Not Run
A34: 33 | B34: TC_DL_003 | C34: Search Online (Download) | D34: Search01_Verify_Navigation | E34: Click icon search góc phải chuyển sang màn Search | F34: Functional | G34: Medium | H34: Mở màn Search từ icon góc phải | I34: Not Run
A35: 34 | B35: TC_DL_004 | C35: Search Online (Download) | D35: Search01_Verify_Navigation | E35: Nhấn BACK từ Search ẩn bàn phím rồi về Home | F35: Functional | G35: Medium | H35: Ẩn bàn phím, sau đó quay về Home | I35: Not Run
A36: 35 | B36: TC_DL_005 | C36: Search Online (Download) | D36: Search02_Verify_Input_And_Suggestions | E36: Gõ ký tự hiển thị danh sách gợi ý | F36: Functional | G36: Medium | H36: Danh sách suggestions hiển thị theo từ khóa | I36: Not Run
A37: 36 | B37: TC_DL_006 | C37: Search Online (Download) | D37: Search02_Verify_Input_And_Suggestions | E37: Gợi ý cập nhật theo từng ký tự nhập thêm | F37: Functional | G37: Medium | H37: Suggestions thay đổi real-time theo input | I37: Not Run
A38: 37 | B38: TC_DL_007 | C38: Search Online (Download) | D38: Search02_Verify_Input_And_Suggestions | E38: Click icon push trong gợi ý chỉ fill textbox không search | F38: Functional | G38: Medium | H38: Từ khóa được điền vào ô tìm kiếm, chưa search | I38: Not Run
A39: 38 | B39: TC_DL_008 | C39: Search Online (Download) | D39: Search02_Verify_Input_And_Suggestions | E39: Clear textbox xóa nội dung tìm kiếm | F39: Functional | G39: Low | H39: Ô tìm kiếm trống sau khi clear | I39: Not Run
A40: 39 | B40: TC_DL_009 | C40: Search Online (Download) | D40: Search02_Verify_Input_And_Suggestions | E40: Query rỗng không trigger search | F40: Negative | G40: Medium | H40: Không có kết quả khi query rỗng | I40: Not Run
A41: 40 | B41: TC_DL_010 | C41: Search Online (Download) | D41: Search02_Verify_Input_And_Suggestions | E41: Click text gợi ý trigger search ra kết quả | F41: Functional | G41: Medium | H41: Hiển thị danh sách kết quả tìm kiếm | I41: Not Run
A42: 41 | B42: TC_DL_011 | C42: Search Online (Download) | D42: Search03_Verify_Results_And_Download | E42: Search query hợp lệ trả về kết quả | F42: Functional | G42: High | H42: Có danh sách kết quả tracks | I42: Not Run
A43: 42 | B43: TC_DL_012 | C43: Search Online (Download) | D43: Search03_Verify_Results_And_Download | E43: Danh sách kết quả hiển thị nhiều tracks | F43: Functional | G43: Medium | H43: Hiển thị tối thiểu 3 tracks | I43: Not Run
... A121: 120 | B121: TC_TRK_047 | C121: Tracks | D121: Tracks05_Verify_Edit_Actions | E121: Delete CANCEL số track không đổi | F121: Functional | G121: Medium | H121: Số lượng track giữ nguyên sau Cancel | I121: Not Run
A122: 121 | B122: TC_TRK_048 | C122: Tracks | D122: Tracks05_Verify_Edit_Actions | E122: Delete thật số track giảm | F122: Functional | G122: High | H122: Track bị xóa, tổng số giảm | I122: Not Run | J122: DESTRUCTIVE
A123: 122 | B123: TC_TRK_049 | C123: Tracks | D123: Tracks06_Verify_Player_Screens | E123: Play Now layout, SeekBar, time hiện tại/tổng, duration M:SS | F123: UI | G123: Medium | H123: Màn Play Now hiển thị đầy đủ, đúng định dạng | I123: Not Run
A124: 123 | B124: TC_TRK_050 | C124: Tracks | D124: Tracks06_Verify_Player_Screens | E124: Controls toggle - Play/Pause, Shuffle, Repeat 3 trạng thái, Heart | F124: Functional | G124: High | H124: Các nút điều khiển toggle đúng | I124: Not Run
A125: 124 | B125: TC_TRK_051 | C125: Tracks | D125: Tracks06_Verify_Player_Screens | E125: Nút Next chuyển bài sau | F125: Functional | G125: High | H125: Chuyển sang bài kế tiếp | I125: Not Run
A126: 125 | B126: TC_TRK_052 | C126: Tracks | D126: Tracks06_Verify_Player_Screens | E126: Nút Previous reset playback | F126: Functional | G126: High | H126: Quay về bài trước / reset bài hiện tại | I126: Not Run
A127: 126 | B127: TC_TRK_053 | C127: Tracks | D127: Tracks06_Verify_Player_Screens | E127: SeekBar drag và tap nhảy vị trí | F127: Functional | G127: Medium | H127: Tua đúng vị trí khi kéo/chạm | I127: Not Run
A128: 127 | B128: TC_TRK_054 | C128: Tracks | D128: Tracks06_Verify_Player_Screens | E128: Icon Add to playlist mở dialog | F128: Functional | G128: Medium | H128: Mở dialog Add to playlist | I128: Not Run
A129: 128 | B129: TC_TRK_055 | C129: Tracks | D129: Tracks06_Verify_Player_Screens | E129: Icon Equalizer mở equalizer | F129: Functional | G129: Medium | H129: Mở equalizer (hệ thống/in-app) | I129: Not Run
A130: 129 | B130: TC_TRK_056 | C130: Tracks | D130: Tracks06_Verify_Player_Screens | E130: Icon Sleep timer mở sleep timer dialog | F130: Functional | G130: Medium | H130: Mở Sleep timer dialog | I130: Not Run
A131: 130 | B131: TC_TRK_057 | C131: Tracks | D131: Tracks06_Verify_Player_Screens | E131: Menu 3 chấm mở edit sheet | F131: Functional | G131: Medium | H131: Mở edit sheet từ Play Now | I131: Not Run
A132: 131 | B132: TC_TRK_058 | C132: Tracks | D132: Tracks06_Verify_Player_Screens | E132: Icon Queue mở Playing Queue, click item phát | F132: Functional | G132: Medium | H132: Mở queue, chọn bài phát đúng | I132: Not Run
A133: 132 | B133: TC_TRK_059 | C133: Tracks | D133: Tracks06_Verify_Player_Screens | E133: Down arrow/Back đóng Play Now, bài vẫn phát | F133: Functional | G133: Medium | H133: Đóng Play Now, nhạc tiếp tục | I133: Not Run
...

Sheet Summary
B2: THỐNG KÊ TEST CASE THEO CHỨC NĂNG
B4: # | C4: Chức năng | D4: Tổng | E4: UI | F4: Functional | G4: Negative | H4: E2E
B5: 1 | C5: Home | D5: =COUNTIF('Test Cases'!$C$2:$C$256,$C5) -> 30 | E5: =COUNTIFS('Test Cases'!$C$2:$C$256,$C5,'Test Cases'!$F$2:$F$256,E$4) -> 9 | F5: =COUNTIFS('Test Cases'!$C$2:$C$256,$C5,'Test Cases'!$F$2:$F$256,F$4) -> 21 | G5: =COUNTIFS('Test Cases'!$C$2:$C$256,$C5,'Test Cases'!$F$2:$F$256,G$4) -> 0 | H5: =COUNTIFS('Test Cases'!$C$2:$C$256,$C5,'Test Cases'!$F$2:$F$256,H$4) -> 0
B6: 2 | C6: Search Online (Download) | D6: =COUNTIF('Test Cases'!$C$2:$C$256,$C6) -> 17 | E6: =COUNTIFS('Test Cases'!$C$2:$C$256,$C6,'Test Cases'!$F$2:$F$256,E$4) -> 1 | F6: =COUNTIFS('Test Cases'!$C$2:$C$256,$C6,'Test Cases'!$F$2:$F$256,F$4) -> 12 | G6: =COUNTIFS('Test Cases'!$C$2:$C$256,$C6,'Test Cases'!$F$2:$F$256,G$4) -> 3 | H6: =COUNTIFS('Test Cases'!$C$2:$C$256,$C6,'Test Cases'!$F$2:$F$256,H$4) -> 1
B7: 3 | C7: Menu (Drawer) | D7: =COUNTIF('Test Cases'!$C$2:$C$256,$C7) -> 26 | E7: =COUNTIFS('Test Cases'!$C$2:$C$256,$C7,'Test Cases'!$F$2:$F$256,E$4) -> 9 | F7: =COUNTIFS('Test Cases'!$C$2:$C$256,$C7,'Test Cases'!$F$2:$F$256,F$4) -> 17 | G7: =COUNTIFS('Test Cases'!$C$2:$C$256,$C7,'Test Cases'!$F$2:$F$256,G$4) -> 0 | H7: =COUNTIFS('Test Cases'!$C$2:$C$256,$C7,'Test Cases'!$F$2:$F$256,H$4) -> 0
B8: 4 | C8: Tracks | D8: =COUNTIF('Test Cases'!$C$2:$C$256,$C8) -> 67 | E8: =COUNTIFS('Test Cases'!$C$2:$C$256,$C8,'Test Cases'!$F$2:$F$256,E$4) -> 7 | F8: =COUNTIFS('Test Cases'!$C$2:$C$256,$C8,'Test Cases'!$F$2:$F$256,F$4) -> 58 | G8: =COUNTIFS('Test Cases'!$C$2:$C$256,$C8,'Test Cases'!$F$2:$F$256,G$4) -> 2 | H8: =COUNTIFS('Test Cases'!$C$2:$C$256,$C8,'Test Cases'!$F$2:$F$256,H$4) -> 0
B9: 5 | C9: Artists | D9: =COUNTIF('Test Cases'!$C$2:$C$256,$C9) -> 46 | E9: =COUNTIFS('Test Cases'!$C$2:$C$256,$C9,'Test Cases'!$F$2:$F$256,E$4) -> 18 | F9: =COUNTIFS('Test Cases'!$C$2:$C$256,$C9,'Test Cases'!$F$2:$F$256,F$4) -> 25 | G9: =COUNTIFS('Test Cases'!$C$2:$C$256,$C9,'Test Cases'!$F$2:$F$256,G$4) -> 3 | H9: =COUNTIFS('Test Cases'!$C$2:$C$256,$C9,'Test Cases'!$F$2:$F$256,H$4) -> 0
B10: 6 | C10: Albums | D10: =COUNTIF('Test Cases'!$C$2:$C$256,$C10) -> 26 | E10: =COUNTIFS('Test Cases'!$C$2:$C$256,$C10,'Test Cases'!$F$2:$F$256,E$4) -> 5 | F10: =COUNTIFS('Test Cases'!$C$2:$C$256,$C10,'Test Cases'!$F$2:$F$256,F$4) -> 19 | G10: =COUNTIFS('Test Cases'!$C$2:$C$256,$C10,'Test Cases'!$F$2:$F$256,G$4) -> 2 | H10: =COUNTIFS('Test Cases'!$C$2:$C$256,$C10,'Test Cases'!$F$2:$F$256,H$4) -> 0
B11: 7 | C11: Playlists | D11: =COUNTIF('Test Cases'!$C$2:$C$256,$C11) -> 22 | E11: =COUNTIFS('Test Cases'!$C$2:$C$256,$C11,'Test Cases'!$F$2:$F$256,E$4) -> 5 | F11: =COUNTIFS('Test Cases'!$C$2:$C$256,$C11,'Test Cases'!$F$2:$F$256,F$4) -> 15 | G11: =COUNTIFS('Test Cases'!$C$2:$C$256,$C11,'Test Cases'!$F$2:$F$256,G$4) -> 2 | H11: =COUNTIFS('Test Cases'!$C$2:$C$256,$C11,'Test Cases'!$F$2:$F$256,H$4) -> 0
B12: 8 | C12: Search In Library | D12: =COUNTIF('Test Cases'!$C$2:$C$256,$C12) -> 21 | E12: =COUNTIFS('Test Cases'!$C$2:$C$256,$C12,'Test Cases'!$F$2:$F$256,E$4) -> 1 | F12: =COUNTIFS('Test Cases'!$C$2:$C$256,$C12,'Test Cases'!$F$2:$F$256,F$4) -> 18 | G12: =COUNTIFS('Test Cases'!$C$2:$C$256,$C12,'Test Cases'!$F$2:$F$256,G$4) -> 2 | H12: =COUNTIFS('Test Cases'!$C$2:$C$256,$C12,'Test Cases'!$F$2:$F$256,H$4) -> 0
C13: TỔNG CỘNG | D13: =SUM(D5:D12) -> 255 | E13: =SUM(E5:E12) -> 55 | F13: =SUM(F5:F12) -> 185 | G13: =SUM(G5:G12) -> 14
B16: THỐNG KÊ THEO ƯU TIÊN
B17: Ưu tiên | C17: Số lượng | D17: Tỷ lệ
B18: High | C18: =COUNTIF('Test Cases'!$G$2:$G$256,$B18) -> 39 | D18: =C18/255 -> 0.15294118
B19: Medium | C19: =COUNTIF('Test Cases'!$G$2:$G$256,$B19) -> 200 | D19: =C19/255 -> 0.78431373
B20: Low | C20: =COUNTIF('Test Cases'!$G$2:$G$256,$B20) -> 16 | D20: =C20/255 -> 0.062745098
B21: TỔNG | C21: =SUM(C18:C20) -> 255 | D21: =C21/255 -> 1
